<mujoco model="spirit">
  <compiler angle="radian" autolimits="true"/>

  <size nconmax = "50" njmax = "50"/>
  <!--  Consider trying default solver-->
  <option timestep='0.001' iterations='100' gravity='0 0 -9.81'/>
  <asset>
    <texture type="skybox" builtin="gradient" rgb1="0.3 0.5 0.7" rgb2="0 0 0" width="512" height="512"/>
    <texture name="texplane" type="2d" builtin="checker" rgb1=".2 .3 .4" rgb2=".1 0.15 0.2" width="512" height="512" mark="cross" markrgb=".8 .8 .8"/>
    <texture name="texgeom" type="cube" builtin="flat" mark="cross" width="127" height="1278"
        rgb1="0.8 0.6 0.4" rgb2="0.8 0.6 0.4" markrgb="1 1 1" random="0.01"/>
    <material name="matplane" reflectance="0.3" texture="texplane" texrepeat="1 1" texuniform="true"/>
    <material name="matgeom" texture="texgeom" texuniform="true" rgba="0.8 0.6 .4 1"/>
  </asset>

  <worldbody>
    <geom name="floor" pos="0 0 -0.5" size="0 0 .25" type="plane" material="matplane" condim="3" contype="2" conaffinity='4'/>
    <light cutoff="100" diffuse="1 1 1" dir="-0 0 -1.3" directional="true" exponent="1" pos="0 0 1.3" specular=".1 .1 .1"/>
    <body>
      <geom size="0.08375 0.12 0.052" pos="-0.08375 0 0" type="box" rgba="0.25 0.25 0.25 1"/>
      <joint type='slide' axis='1 0 0' limited='false'/>
      <joint type='slide' axis='0 1 0' limited='false'/>
      <joint type='slide' axis='0 0 1' limited='false' ref='1.01'/>
      <joint type='ball' limited='false'/>
      <body name="hip1" pos="-0.2263 0.07 0">
        <inertial pos="0 0 0" quat="0.5 0.5 -0.5 0.5" mass="0.575" diaginertia="0.000869688 0.000669635 0.000669635"/>
        <joint name="joint_9" pos="0 0 0" axis="1 0 0" range="-0.707 0.707"/>
        <geom size="0.055 0.04" pos="0 0.028 0" quat="0.707107 0.707107 0 0" type="cylinder" rgba="0.68 0.34 0.08 1"/>
        <body name="upper1" pos="0 0.10098 0">
          <inertial pos="0 0 0" quat="0.5 0.5 0.5 0.5" mass="0.775" diaginertia="0.001 0.001 5e-05"/>
          <joint name="joint_2" pos="0 0 0" axis="0 -1 0" range="-6.28319 6.28319"/>
          <geom size="0.103 0.011 0.0275" pos="-0.103 -0.022 0" type="box" rgba="0.68 0.68 0.68 1"/>
          <body name="lower1" pos="-0.206 0 0">
            <inertial pos="0.0343333 0 0" quat="0.5 0.5 0.5 0.5" mass="0.09" diaginertia="0.00065545 0.00065545 3e-05"/>
            <joint name="joint_3" pos="0 0 0" axis="0 1 0" range="0 3.14159"/>
            <geom size="0.013 0.103" pos="0.103 0 0" quat="0.707107 0 0.707107 0" type="cylinder" rgba="0.68 0.68 0.68 1"/>
            <geom size="0.02" pos="0.206 0 0" rgba="0.1 0.1 0.1 1"/>
          </body>
        </body>
      </body>
      <body name="hip3" pos="-0.2263 -0.07 0">
        <inertial pos="0 0 0" quat="0.5 0.5 -0.5 0.5" mass="0.575" diaginertia="0.000869688 0.000669635 0.000669635"/>
        <joint name="joint_11" pos="0 0 0" axis="1 0 0" range="-0.707 0.707"/>
        <geom size="0.055 0.04" pos="0 -0.028 0" quat="0.707107 0.707107 0 0" type="cylinder" rgba="0.68 0.34 0.08 1"/>
        <body name="upper3" pos="0 -0.10098 0">
          <inertial pos="0 0 0" quat="0.5 0.5 0.5 0.5" mass="0.775" diaginertia="0.001 0.001 5e-05"/>
          <joint name="joint_6" pos="0 0 0" axis="0 -1 0" range="-6.28319 6.28319"/>
          <geom size="0.103 0.011 0.0275" pos="-0.103 0.022 0" type="box" rgba="0.68 0.68 0.68 1"/>
          <body name="lower3" pos="-0.206 0 0">
            <inertial pos="0.0343333 0 0" quat="0.5 0.5 0.5 0.5" mass="0.09" diaginertia="0.00065545 0.00065545 3e-05"/>
            <joint name="joint_7" pos="0 0 0" axis="0 1 0" range="0 3.14159"/>
            <geom size="0.013 0.103" pos="0.103 0 0" quat="0.707107 0 0.707107 0" type="cylinder" rgba="0.68 0.68 0.68 1"/>
            <geom size="0.02" pos="0.206 0 0" rgba="0.1 0.1 0.1 1"/>
          </body>
        </body>
      </body>
      <body name="front_body" pos="0.08375 0 0">
        <inertial pos="0 0 0" quat="0.5 0.5 -0.5 0.5" mass="2.875" diaginertia="0.0252 0.025 0.0156"/>
        <joint name="joint_12" pos="0 0 0" axis="1 0 0" range="-0.707 0.707"/>
        <geom size="0.08375 0.12 0.052" pos="0.08375 0 0" type="box" rgba="0.25 0.25 0.25 1"/>
        <body name="hip0" pos="0.14255 0.07 0">
          <inertial pos="0 0 0" quat="0.5 0.5 -0.5 0.5" mass="0.575" diaginertia="0.000869688 0.000669635 0.000669635"/>
          <joint name="joint_8" pos="0 0 0" axis="1 0 0" range="-0.707 0.707"/>
          <geom size="0.055 0.04" pos="0 0.028 0" quat="0.707107 0.707107 0 0" type="cylinder" rgba="0.68 0.34 0.08 1"/>
          <body name="upper0" pos="0 0.10098 0">
            <inertial pos="0 0 0" quat="0.5 0.5 0.5 0.5" mass="0.775" diaginertia="0.001 0.001 5e-05"/>
            <joint name="joint_0" pos="0 0 0" axis="0 -1 0" range="-6.28319 6.28319"/>
            <geom size="0.103 0.011 0.0275" pos="-0.103 -0.022 0" type="box" rgba="0.68 0.68 0.68 1"/>
            <body name="lower0" pos="-0.206 0 0">
              <inertial pos="0.0343333 0 0" quat="0.5 0.5 0.5 0.5" mass="0.09" diaginertia="0.00065545 0.00065545 3e-05"/>
              <joint name="joint_1" pos="0 0 0" axis="0 1 0" range="0 3.14159"/>
              <geom size="0.013 0.103" pos="0.103 0 0" quat="0.707107 0 0.707107 0" type="cylinder" rgba="0.68 0.68 0.68 1"/>
              <geom size="0.02" pos="0.206 0 0" rgba="0.1 0.1 0.1 1"/>
            </body>
          </body>
        </body>
        <body name="hip2" pos="0.14255 -0.07 0">
          <inertial pos="0 0 0" quat="0.5 0.5 -0.5 0.5" mass="0.575" diaginertia="0.000869688 0.000669635 0.000669635"/>
          <joint name="joint_10" pos="0 0 0" axis="1 0 0" range="-0.707 0.707"/>
          <geom size="0.055 0.04" pos="0 -0.028 0" quat="0.707107 0.707107 0 0" type="cylinder" rgba="0.68 0.34 0.08 1"/>
          <body name="upper2" pos="0 -0.10098 0">
            <inertial pos="0 0 0" quat="0.5 0.5 0.5 0.5" mass="0.775" diaginertia="0.001 0.001 5e-05"/>
            <joint name="joint_4" pos="0 0 0" axis="0 -1 0" range="-6.28319 6.28319"/>
            <geom size="0.103 0.011 0.0275" pos="-0.103 0.022 0" type="box" rgba="0.68 0.68 0.68 1"/>
            <body name="lower2" pos="-0.206 0 0">
              <inertial pos="0.0343333 0 0" quat="0.5 0.5 0.5 0.5" mass="0.09" diaginertia="0.00065545 0.00065545 3e-05"/>
              <joint name="joint_5" pos="0 0 0" axis="0 1 0" range="0 3.14159"/>
              <geom size="0.013 0.103" pos="0.103 0 0" quat="0.707107 0 0.707107 0" type="cylinder" rgba="0.68 0.68 0.68 1"/>
              <geom size="0.02" pos="0.206 0 0" rgba="0.1 0.1 0.1 1"/>
            </body>
          </body>
        </body>
      </body>

    </body>
  </worldbody>
</mujoco>
